# Exception Handling in JavaScript

## Introduction

Exception handling in JavaScript allows you to gracefully handle unexpected errors and exceptions that may occur during the execution of your code. By using try-catch blocks, you can prevent your program from crashing and handle errors in a controlled manner. 
In this tutorial, we'll start with the basic try-catch statement and then extend it to include the finally block for more comprehensive exception handling.

## Basic Try-Catch Statement

The basic try-catch statement is used to wrap a block of code that might throw an exception. If an exception occurs within the try block, it is caught by the catch block, and you can handle the error accordingly.

### Example using Basic Try-Catch

```javascript
// A function that divides two numbers
function divideNumbers(a, b) {
  try {
    if (b === 0) {
      throw new Error("Cannot divide by zero.");
    }
    return a / b;
  } catch (error) {
    // Handling the exception
    console.log("Error:", error.message);
    return null;
  }
}

// Calling the function with valid arguments
const result1 = divideNumbers(10, 2);
// Output: 5
console.log(result1);

// Calling the function with an invalid argument (division by zero)
const result2 = divideNumbers(10, 0);
// Output: Error: Cannot divide by zero.
//         null
console.log(result2);
```

## Try-Catch-Finally Statement

The try-catch-finally statement extends the basic try-catch statement by including a finally block. The finally block allows you to execute code that should always run, regardless of whether an exception was thrown or not. This is useful for cleanup tasks or releasing resources.

### Example using Try-Catch-Finally

```javascript
// A function that reads data from a file and releases resources in the finally block
function readFileAndCleanup() {
  let fileHandle;
  try {
    fileHandle = openFile(); // A fictional function that opens a file
    // Reading data from the file
    // Code that may throw an exception
    return "Data from the file";
  } catch (error) {
    // Handling the exception
    console.log("Error:", error.message);
    return null;
  } finally {
    if (fileHandle) {
      closeFile(fileHandle); // A fictional function that closes the file
    }
    console.log("Cleanup completed.");
  }
}

// Calling the function
const data = readFileAndCleanup();
// Output: Error: File not found.
//         Cleanup completed.
console.log(data);
```

## Nested Try-Catch

You can also use nested try-catch blocks to handle different types of exceptions separately.

### Example using Nested Try-Catch

```javascript
function divideNumbers(a, b) {
  try {
    if (b === 0) {
      throw new Error("Cannot divide by zero.");
    }
    return a / b;
  } catch (error) {
    console.log("Error:", error.message);
    try {
      // Attempting an alternative operation
      return a * b;
    } catch (error) {
      console.log("Error in alternative operation:", error.message);
      return null;
    }
  }
}

const result1 = divideNumbers(10, 2);
// Output: 5
console.log(result1);

const result2 = divideNumbers(10, 0);
// Output: Error: Cannot divide by zero.
//         Error in alternative operation: Cannot read property 'message' of undefined
//         null
console.log(result2);
```

## Conclusion

In this tutorial, we learned about exceptional handling in JavaScript using the try-catch statement. We saw how to handle errors and exceptions that might occur during the execution of our code, preventing the program from crashing. Additionally, we explored the try-catch-finally statement to perform cleanup tasks or release resources after handling an exception. 
Exception handling is crucial for writing robust and reliable JavaScript code, ensuring that your applications gracefully handle unexpected situations and recover from errors smoothly. Happy coding!